Workbook

Sheet Internal Tracker
A1: Area | B1: Predicted Votes | C1: Actual Votes | D1: Jackson % Predicted | E1: Jackson Count Predicted | F1: Jones % Predicted | G1: Jones Count Predicted | H1: ROF % Predicted | I1: ROF Count Predicted
A2: Cobb | B2: =CountyTops!E6 -> 67850.6 | D2: 0.34 | E2: =B2*D2 -> 23069.204 | F2: 0.25 | G2: =B2*F2 -> 16962.65 | H2: 0.41 | I2: =B2-(E2+G2) -> 27818.746
A3: Gwinnett | B3: =CountyTops!E7 -> 54995.7 | D3: 0.35 | E3: =B3*D3 -> 19248.495 | F3: 0.27 | G3: =B3*F3 -> 14848.839 | H3: 0.38 | I3: =B3-(E3+G3) -> 20898.366
A4: Fulton | B4: =CountyTops!E8 -> 47204.3 | D4: 0.34 | E4: =B4*D4 -> 16049.462 | F4: 0.24 | G4: =B4*F4 -> 11329.032 | H4: 0.42 | I4: =B4-(E4+G4) -> 19825.806
A5: Cherokee | B5: =CountyTops!E9 -> 36394.2 | D5: 0.42 | E5: =B5*D5 -> 15285.564 | F5: 0.23 | G5: =B5*F5 -> 8370.666 | H5: 0.35 | I5: =B5-(E5+G5) -> 12737.97
A6: Forsyth | B6: =CountyTops!E10 -> 30326.3 | D6: 0.4 | E6: =B6*D6 -> 12130.52 | F6: 0.3 | G6: =B6*F6 -> 9097.89 | H6: 0.3 | I6: =B6-(E6+G6) -> 9097.89
A7: Hall | B7: =CountyTops!E11 -> 24588.3 | D7: 0.36 | E7: =B7*D7 -> 8851.788 | F7: 0.28 | G7: =B7*F7 -> 6884.724 | H7: 0.36 | I7: =B7-(E7+G7) -> 8851.788
A8: DeKalb | B8: =CountyTops!E12 -> 22326.8 | D8: 0.44 | E8: =B8*D8 -> 9823.792 | F8: 0.25 | G8: =B8*F8 -> 5581.7 | H8: 0.31 | I8: =B8-(E8+G8) -> 6921.308
A9: Columbia | B9: =CountyTops!E13 -> 18897.9 | D9: 0.46 | E9: =B9*D9 -> 8693.034 | F9: 0.3 | G9: =B9*F9 -> 5669.37 | H9: 0.24 | I9: =B9-(E9+G9) -> 4535.496
A10: Chatham | B10: =CountyTops!E14 -> 18257.1 | D10: 0.37 | E10: =B10*D10 -> 6755.127 | F10: 0.29 | G10: =B10*F10 -> 5294.559 | H10: 0.34 | I10: =B10-(E10+G10) -> 6207.414
A11: Coweta | B11: =CountyTops!E15 -> 17804.8 | D11: 0.4 | E11: =B11*D11 -> 7121.92 | F11: 0.35 | G11: =B11*F11 -> 6231.68 | H11: 0.25 | I11: =B11-(E11+G11) -> 4451.2
A12: Paulding | B12: =CountyTops!E16 -> 17306.2 | D12: 0.37 | E12: =B12*D12 -> 6403.294 | F12: 0.28 | G12: =B12*F12 -> 4845.736 | H12: 0.35 | I12: =B12-(E12+G12) -> 6057.17
A13: Henry | B13: =CountyTops!E17 -> 17008.4 | D13: 0.34 | E13: =B13*D13 -> 5782.856 | F13: 0.32 | G13: =B13*F13 -> 5442.688 | H13: 0.34 | I13: =B13-(E13+G13) -> 5782.856
... A24: Glynn | B24: =CountyTops!E28 -> 9843.1 | D24: 0.47 | E24: =B24*D24 -> 4626.257 | F24: 0.27 | G24: =B24*F24 -> 2657.637 | H24: 0.26 | I24: =B24-(E24+G24) -> 2559.206
A25: Small | B25: =sum(CountyTops!E29:E52,CountyTops!E54,CountyTops!E58,CountyTops!E59) -> 179600.3 | D25: 0.39 | E25: =B25*D25 -> 70044.117 | F25: 0.34 | G25: =B25*F25 -> 61064.102 | H25: 0.27 | I25: =B25-(E25+G25) -> 48492.081
A26: Very Small | B26: =sum(CountyTops!E53,CountyTops!E55:E57,CountyTops!E60:E135) -> 209092.6 | D26: 0.34 | E26: =B26*D26 -> 71091.484 | F26: 0.38 | G26: =B26*F26 -> 79455.188 | H26: 0.28 | I26: =B26-(E26+G26) -> 58545.928
A27: Micro | B27: =sum(CountyTops!E136:E164) -> 16188.7 | D27: 0.37 | E27: =B27*D27 -> 5989.819 | F27: 0.38 | G27: =B27*F27 -> 6151.706 | H27: 0.25 | I27: =B27-(E27+G27) -> 4047.175

Sheet External Tracker Data
A1: Area | B1: =IFERROR(__xludf.DUMMYFUNCTION("QUERY(IMPORTRANGE(""https://docs.google.com/spreadsheets/d/1o4vVTAcm9zeWOMn_hTEttk3OfwEP1tRR6DEg7aESAZg/edit?gid=904754529#gid=904754529"", ""ReportingTop!A:Z""), ""Select *"")"),"29 ") -> 29 | C1: =IFERROR(__xludf.DUMMYFUNCTION("""COMPUTED_VALUE""")," DMA ") -> DMA | D1: =IFERROR(__xludf.DUMMYFUNCTION("""COMPUTED_VALUE""")," Name ") -> Name | E1: =IFERROR(__xludf.DUMMYFUNCTION("""COMPUTED_VALUE""")," Active Registered Voters ") -> Active Registered Voters | F1: =IFERROR(__xludf.DUMMYFUNCTION("""COMPUTED_VALUE""")," Projected Turnout ") -> Projected Turnout | G1: =IFERROR(__xludf.DUMMYFUNCTION("""COMPUTED_VALUE""")," Total Precincts ") -> Total Precincts | H1: =IFERROR(__xludf.DUMMYFUNCTION("""COMPUTED_VALUE""")," Precincts Reported ") -> Precincts Reported | I1: =IFERROR(__xludf.DUMMYFUNCTION("""COMPUTED_VALUE""")," Precincts Reported % #DIV/0!") -> Precincts Reported % #DIV/0! | J1: =IFERROR(__xludf.DUMMYFUNCTION("""COMPUTED_VALUE""")," AB Dropped? ") -> AB Dropped? | K1: =IFERROR(__xludf.DUMMYFUNCTION("""COMPUTED_VALUE""")," EV Dropped? ") -> EV Dropped? | L1: =IFERROR(__xludf.DUMMYFUNCTION("""COMPUTED_VALUE""")," Ballots Cast ") -> Ballots Cast | M1: =IFERROR(__xludf.DUMMYFUNCTION("""COMPUTED_VALUE""")," Provisional Ballots ") -> Provisional Ballots | N1: =IFERROR(__xludf.DUMMYFUNCTION("""COMPUTED_VALUE""")," Projected Remaining Ballots 0") -> Projected Remaining Ballots 0 | O1: =IFERROR(__xludf.DUMMYFUNCTION("""COMPUTED_VALUE""")," JACKSON 1") -> JACKSON 1 | P1: =IFERROR(__xludf.DUMMYFUNCTION("""COMPUTED_VALUE""")," JACKSON % #REF!") -> JACKSON % #REF! | Q1: =IFERROR(__xludf.DUMMYFUNCTION("""COMPUTED_VALUE""")," JONES 2") -> JONES 2 | R1: =IFERROR(__xludf.DUMMYFUNCTION("""COMPUTED_VALUE""")," JONES % #REF!") -> JONES % #REF! | S1: =IFERROR(__xludf.DUMMYFUNCTION("""COMPUTED_VALUE""")," RAFFENSPERGER 3") -> RAFFENSPERGER 3 | T1: =IFERROR(__xludf.DUMMYFUNCTION("""COMPUTED_VALUE""")," RAFFENSPERGER % #REF!") -> RAFFENSPERGER % #REF! | U1: =IFERROR(__xludf.DUMMYFUNCTION("""COMPUTED_VALUE""")," CARR ") -> CARR | V1: =IFERROR(__xludf.DUMMYFUNCTION("""COMPUTED_VALUE""")," CARR % #REF!") -> CARR % #REF! | W1: =IFERROR(__xludf.DUMMYFUNCTION("""COMPUTED_VALUE""")," OTHER #REF!") -> OTHER #REF! | X1: =IFERROR(__xludf.DUMMYFUNCTION("""COMPUTED_VALUE""")," OTHER % #REF!") -> OTHER % #REF! | Y1: =IFERROR(__xludf.DUMMYFUNCTION("""COMPUTED_VALUE""")," TOTAL VOTES #REF!") -> TOTAL VOTES #REF! | Z1: =IFERROR(__xludf.DUMMYFUNCTION("""COMPUTED_VALUE""")," ") | AA1: =IFERROR(__xludf.DUMMYFUNCTION("""COMPUTED_VALUE""")," ")
A2: {=XLOOKUP(D2, CountyTops!D:D, CountyTops!B:B, "")} -> Very Small | C2: =IFERROR(__xludf.DUMMYFUNCTION("""COMPUTED_VALUE"""),"Savannah") -> Savannah | D2: =IFERROR(__xludf.DUMMYFUNCTION("""COMPUTED_VALUE"""),"Appling") -> Appling | I2: =IFERROR(__xludf.DUMMYFUNCTION("""COMPUTED_VALUE"""),"#DIV/0!") -> #DIV/0! | N2: =IFERROR(__xludf.DUMMYFUNCTION("""COMPUTED_VALUE"""),0.0) -> 0 | O2: =IFERROR(__xludf.DUMMYFUNCTION("""COMPUTED_VALUE"""),1.0) -> 1 | P2: =IFERROR(__xludf.DUMMYFUNCTION("""COMPUTED_VALUE"""),0.3333333333333333) -> 0.33333333 | Q2: =IFERROR(__xludf.DUMMYFUNCTION("""COMPUTED_VALUE"""),2.0) -> 2 | R2: =IFERROR(__xludf.DUMMYFUNCTION("""COMPUTED_VALUE"""),0.6666666666666666) -> 0.66666667 | S2: =IFERROR(__xludf.DUMMYFUNCTION("""COMPUTED_VALUE"""),3.0) -> 3 | T2: =IFERROR(__xludf.DUMMYFUNCTION("""COMPUTED_VALUE"""),"#DIV/0!") -> #DIV/0! | U2: =IFERROR(__xludf.DUMMYFUNCTION("""COMPUTED_VALUE"""),0.7148) -> 0.7148 | V2: =IFERROR(__xludf.DUMMYFUNCTION("""COMPUTED_VALUE"""),4.0) -> 4 | W2: =IFERROR(__xludf.DUMMYFUNCTION("""COMPUTED_VALUE"""),"#REF!") -> #REF! | X2: =IFERROR(__xludf.DUMMYFUNCTION("""COMPUTED_VALUE"""),5.0) -> 5 | Y2: =IFERROR(__xludf.DUMMYFUNCTION("""COMPUTED_VALUE"""),36.0) -> 36
A3: {=XLOOKUP(D3, CountyTops!D:D, CountyTops!B:B, "")} -> Micro | C3: =IFERROR(__xludf.DUMMYFUNCTION("""COMPUTED_VALUE"""),"Albany") -> Albany | D3: =IFERROR(__xludf.DUMMYFUNCTION("""COMPUTED_VALUE"""),"Atkinson") -> Atkinson | I3: =IFERROR(__xludf.DUMMYFUNCTION("""COMPUTED_VALUE"""),"#DIV/0!") -> #DIV/0! | N3: =IFERROR(__xludf.DUMMYFUNCTION("""COMPUTED_VALUE"""),0.0) -> 0
A4: {=XLOOKUP(D4, CountyTops!D:D, CountyTops!B:B, "")} -> Very Small | C4: =IFERROR(__xludf.DUMMYFUNCTION("""COMPUTED_VALUE"""),"Savannah") -> Savannah | D4: =IFERROR(__xludf.DUMMYFUNCTION("""COMPUTED_VALUE"""),"Bacon") -> Bacon | I4: =IFERROR(__xludf.DUMMYFUNCTION("""COMPUTED_VALUE"""),"#DIV/0!") -> #DIV/0! | N4: =IFERROR(__xludf.DUMMYFUNCTION("""COMPUTED_VALUE"""),0.0) -> 0
A5: {=XLOOKUP(D5, CountyTops!D:D, CountyTops!B:B, "")} -> Micro | C5: =IFERROR(__xludf.DUMMYFUNCTION("""COMPUTED_VALUE"""),"Albany") -> Albany | D5: =IFERROR(__xludf.DUMMYFUNCTION("""COMPUTED_VALUE"""),"Baker") -> Baker | I5: =IFERROR(__xludf.DUMMYFUNCTION("""COMPUTED_VALUE"""),"#DIV/0!") -> #DIV/0! | N5: =IFERROR(__xludf.DUMMYFUNCTION("""COMPUTED_VALUE"""),0.0) -> 0
A6: {=XLOOKUP(D6, CountyTops!D:D, CountyTops!B:B, "")} -> Very Small | C6: =IFERROR(__xludf.DUMMYFUNCTION("""COMPUTED_VALUE"""),"Macon") -> Macon | D6: =IFERROR(__xludf.DUMMYFUNCTION("""COMPUTED_VALUE"""),"Baldwin") -> Baldwin | I6: =IFERROR(__xludf.DUMMYFUNCTION("""COMPUTED_VALUE"""),"#DIV/0!") -> #DIV/0! | N6: =IFERROR(__xludf.DUMMYFUNCTION("""COMPUTED_VALUE"""),0.0) -> 0
A7: {=XLOOKUP(D7, CountyTops!D:D, CountyTops!B:B, "")} -> Very Small | C7: =IFERROR(__xludf.DUMMYFUNCTION("""COMPUTED_VALUE"""),"Atlanta") -> Atlanta | D7: =IFERROR(__xludf.DUMMYFUNCTION("""COMPUTED_VALUE"""),"Banks") -> Banks | I7: =IFERROR(__xludf.DUMMYFUNCTION("""COMPUTED_VALUE"""),"#DIV/0!") -> #DIV/0! | N7: =IFERROR(__xludf.DUMMYFUNCTION("""COMPUTED_VALUE"""),0.0) -> 0
A8: {=XLOOKUP(D8, CountyTops!D:D, CountyTops!B:B, "")} -> Small | C8: =IFERROR(__xludf.DUMMYFUNCTION("""COMPUTED_VALUE"""),"Atlanta") -> Atlanta | D8: =IFERROR(__xludf.DUMMYFUNCTION("""COMPUTED_VALUE"""),"Barrow") -> Barrow | I8: =IFERROR(__xludf.DUMMYFUNCTION("""COMPUTED_VALUE"""),"#DIV/0!") -> #DIV/0! | N8: =IFERROR(__xludf.DUMMYFUNCTION("""COMPUTED_VALUE"""),0.0) -> 0
A9: {=XLOOKUP(D9, CountyTops!D:D, CountyTops!B:B, "")} -> Mid-Small | C9: =IFERROR(__xludf.DUMMYFUNCTION("""COMPUTED_VALUE"""),"Atlanta") -> Atlanta | D9: =IFERROR(__xludf.DUMMYFUNCTION("""COMPUTED_VALUE"""),"Bartow") -> Bartow | I9: =IFERROR(__xludf.DUMMYFUNCTION("""COMPUTED_VALUE"""),"#DIV/0!") -> #DIV/0! | N9: =IFERROR(__xludf.DUMMYFUNCTION("""COMPUTED_VALUE"""),0.0) -> 0
A10: {=XLOOKUP(D10, CountyTops!D:D, CountyTops!B:B, "")} -> Very Small | C10: =IFERROR(__xludf.DUMMYFUNCTION("""COMPUTED_VALUE"""),"Albany") -> Albany | D10: =IFERROR(__xludf.DUMMYFUNCTION("""COMPUTED_VALUE"""),"Ben Hill") -> Ben Hill | I10: =IFERROR(__xludf.DUMMYFUNCTION("""COMPUTED_VALUE"""),"#DIV/0!") -> #DIV/0! | N10: =IFERROR(__xludf.DUMMYFUNCTION("""COMPUTED_VALUE"""),0.0) -> 0
A11: {=XLOOKUP(D11, CountyTops!D:D, CountyTops!B:B, "")} -> Very Small | C11: =IFERROR(__xludf.DUMMYFUNCTION("""COMPUTED_VALUE"""),"Albany") -> Albany | D11: =IFERROR(__xludf.DUMMYFUNCTION("""COMPUTED_VALUE"""),"Berrien") -> Berrien | I11: =IFERROR(__xludf.DUMMYFUNCTION("""COMPUTED_VALUE"""),"#DIV/0!") -> #DIV/0! | N11: =IFERROR(__xludf.DUMMYFUNCTION("""COMPUTED_VALUE"""),0.0) -> 0
A12: {=XLOOKUP(D12, CountyTops!D:D, CountyTops!B:B, "")} -> Mid-Small | C12: =IFERROR(__xludf.DUMMYFUNCTION("""COMPUTED_VALUE"""),"Macon") -> Macon | D12: =IFERROR(__xludf.DUMMYFUNCTION("""COMPUTED_VALUE"""),"Bibb") -> Bibb | I12: =IFERROR(__xludf.DUMMYFUNCTION("""COMPUTED_VALUE"""),"#DIV/0!") -> #DIV/0! | N12: =IFERROR(__xludf.DUMMYFUNCTION("""COMPUTED_VALUE"""),0.0) -> 0
A13: {=XLOOKUP(D13, CountyTops!D:D, CountyTops!B:B, "")} -> Very Small | C13: =IFERROR(__xludf.DUMMYFUNCTION("""COMPUTED_VALUE"""),"Macon") -> Macon | D13: =IFERROR(__xludf.DUMMYFUNCTION("""COMPUTED_VALUE"""),"Bleckley") -> Bleckley | I13: =IFERROR(__xludf.DUMMYFUNCTION("""COMPUTED_VALUE"""),"#DIV/0!") -> #DIV/0! | N13: =IFERROR(__xludf.DUMMYFUNCTION("""COMPUTED_VALUE"""),0.0) -> 0
A14: {=XLOOKUP(D14, CountyTops!D:D, CountyTops!B:B, "")} -> Very Small | C14: =IFERROR(__xludf.DUMMYFUNCTION("""COMPUTED_VALUE"""),"Jacksonville, FL") -> Jacksonville, FL | D14: =IFERROR(__xludf.DUMMYFUNCTION("""COMPUTED_VALUE"""),"Brantley") -> Brantley | I14: =IFERROR(__xludf.DUMMYFUNCTION("""COMPUTED_VALUE"""),"#DIV/0!") -> #DIV/0! | N14: =IFERROR(__xludf.DUMMYFUNCTION("""COMPUTED_VALUE"""),0.0) -> 0
A15: {=XLOOKUP(D15, CountyTops!D:D, CountyTops!B:B, "")} -> Very Small | C15: =IFERROR(__xludf.DUMMYFUNCTION("""COMPUTED_VALUE"""),"Tallahassee, FL") -> Tallahassee, FL | D15: =IFERROR(__xludf.DUMMYFUNCTION("""COMPUTED_VALUE"""),"Brooks") -> Brooks | I15: =IFERROR(__xludf.DUMMYFUNCTION("""COMPUTED_VALUE"""),"#DIV/0!") -> #DIV/0! | N15: =IFERROR(__xludf.DUMMYFUNCTION("""COMPUTED_VALUE"""),0.0) -> 0
A16: {=XLOOKUP(D16, CountyTops!D:D, CountyTops!B:B, "")} -> Very Small | C16: =IFERROR(__xludf.DUMMYFUNCTION("""COMPUTED_VALUE"""),"Savannah") -> Savannah | D16: =IFERROR(__xludf.DUMMYFUNCTION("""COMPUTED_VALUE"""),"Bryan") -> Bryan | I16: =IFERROR(__xludf.DUMMYFUNCTION("""COMPUTED_VALUE"""),"#DIV/0!") -> #DIV/0! | N16: =IFERROR(__xludf.DUMMYFUNCTION("""COMPUTED_VALUE"""),0.0) -> 0
A17: {=XLOOKUP(D17, CountyTops!D:D, CountyTops!B:B, "")} -> Small | C17: =IFERROR(__xludf.DUMMYFUNCTION("""COMPUTED_VALUE"""),"Savannah") -> Savannah | D17: =IFERROR(__xludf.DUMMYFUNCTION("""COMPUTED_VALUE"""),"Bulloch") -> Bulloch | I17: =IFERROR(__xludf.DUMMYFUNCTION("""COMPUTED_VALUE"""),"#DIV/0!") -> #DIV/0! | N17: =IFERROR(__xludf.DUMMYFUNCTION("""COMPUTED_VALUE"""),0.0) -> 0
A18: {=XLOOKUP(D18, CountyTops!D:D, CountyTops!B:B, "")} -> Very Small | C18: =IFERROR(__xludf.DUMMYFUNCTION("""COMPUTED_VALUE"""),"Augusta") -> Augusta | D18: =IFERROR(__xludf.DUMMYFUNCTION("""COMPUTED_VALUE"""),"Burke") -> Burke | I18: =IFERROR(__xludf.DUMMYFUNCTION("""COMPUTED_VALUE"""),"#DIV/0!") -> #DIV/0! | N18: =IFERROR(__xludf.DUMMYFUNCTION("""COMPUTED_VALUE"""),0.0) -> 0
A19: {=XLOOKUP(D19, CountyTops!D:D, CountyTops!B:B, "")} -> Very Small | C19: =IFERROR(__xludf.DUMMYFUNCTION("""COMPUTED_VALUE"""),"Atlanta") -> Atlanta | D19: =IFERROR(__xludf.DUMMYFUNCTION("""COMPUTED_VALUE"""),"Butts") -> Butts | I19: =IFERROR(__xludf.DUMMYFUNCTION("""COMPUTED_VALUE"""),"#DIV/0!") -> #DIV/0! | N19: =IFERROR(__xludf.DUMMYFUNCTION("""COMPUTED_VALUE"""),0.0) -> 0
A20: {=XLOOKUP(D20, CountyTops!D:D, CountyTops!B:B, "")} -> Micro | C20: =IFERROR(__xludf.DUMMYFUNCTION("""COMPUTED_VALUE"""),"Albany") -> Albany | D20: =IFERROR(__xludf.DUMMYFUNCTION("""COMPUTED_VALUE"""),"Calhoun") -> Calhoun | I20: =IFERROR(__xludf.DUMMYFUNCTION("""COMPUTED_VALUE"""),"#DIV/0!") -> #DIV/0! | N20: =IFERROR(__xludf.DUMMYFUNCTION("""COMPUTED_VALUE"""),0.0) -> 0
A21: {=XLOOKUP(D21, CountyTops!D:D, CountyTops!B:B, "")} -> Small | C21: =IFERROR(__xludf.DUMMYFUNCTION("""COMPUTED_VALUE"""),"Jacksonville, FL") -> Jacksonville, FL | D21: =IFERROR(__xludf.DUMMYFUNCTION("""COMPUTED_VALUE"""),"Camden") -> Camden | I21: =IFERROR(__xludf.DUMMYFUNCTION("""COMPUTED_VALUE"""),"#DIV/0!") -> #DIV/0! | N21: =IFERROR(__xludf.DUMMYFUNCTION("""COMPUTED_VALUE"""),0.0) -> 0
A22: {=XLOOKUP(D22, CountyTops!D:D, CountyTops!B:B, "")} -> Very Small | C22: =IFERROR(__xludf.DUMMYFUNCTION("""COMPUTED_VALUE"""),"Savannah") -> Savannah | D22: =IFERROR(__xludf.DUMMYFUNCTION("""COMPUTED_VALUE"""),"Candler") -> Candler | I22: =IFERROR(__xludf.DUMMYFUNCTION("""COMPUTED_VALUE"""),"#DIV/0!") -> #DIV/0! | N22: =IFERROR(__xludf.DUMMYFUNCTION("""COMPUTED_VALUE"""),0.0) -> 0
A23: {=XLOOKUP(D23, CountyTops!D:D, CountyTops!B:B, "")} -> Mid-Small | C23: =IFERROR(__xludf.DUMMYFUNCTION("""COMPUTED_VALUE"""),"Atlanta") -> Atlanta | D23: =IFERROR(__xludf.DUMMYFUNCTION("""COMPUTED_VALUE"""),"Carroll") -> Carroll | I23: =IFERROR(__xludf.DUMMYFUNCTION("""COMPUTED_VALUE"""),"#DIV/0!") -> #DIV/0! | N23: =IFERROR(__xludf.DUMMYFUNCTION("""COMPUTED_VALUE"""),0.0) -> 0
A24: {=XLOOKUP(D24, CountyTops!D:D, CountyTops!B:B, "")} -> Small | C24: =IFERROR(__xludf.DUMMYFUNCTION("""COMPUTED_VALUE"""),"Chattanooga") -> Chattanooga | D24: =IFERROR(__xludf.DUMMYFUNCTION("""COMPUTED_VALUE"""),"Catoosa") -> Catoosa | I24: =IFERROR(__xludf.DUMMYFUNCTION("""COMPUTED_VALUE"""),"#DIV/0!") -> #DIV/0! | N24: =IFERROR(__xludf.DUMMYFUNCTION("""COMPUTED_VALUE"""),0.0) -> 0
A25: {=XLOOKUP(D25, CountyTops!D:D, CountyTops!B:B, "")} -> Very Small | C25: =IFERROR(__xludf.DUMMYFUNCTION("""COMPUTED_VALUE"""),"Jacksonville, FL") -> Jacksonville, FL | D25: =IFERROR(__xludf.DUMMYFUNCTION("""COMPUTED_VALUE"""),"Charlton") -> Charlton | I25: =IFERROR(__xludf.DUMMYFUNCTION("""COMPUTED_VALUE"""),"#DIV/0!") -> #DIV/0! | N25: =IFERROR(__xludf.DUMMYFUNCTION("""COMPUTED_VALUE"""),0.0) -> 0
A26: {=XLOOKUP(D26, CountyTops!D:D, CountyTops!B:B, "")} -> Mid-Large | C26: =IFERROR(__xludf.DUMMYFUNCTION("""COMPUTED_VALUE"""),"Savannah") -> Savannah | D26: =IFERROR(__xludf.DUMMYFUNCTION("""COMPUTED_VALUE"""),"Chatham") -> Chatham | I26: =IFERROR(__xludf.DUMMYFUNCTION("""COMPUTED_VALUE"""),"#DIV/0!") -> #DIV/0! | N26: =IFERROR(__xludf.DUMMYFUNCTION("""COMPUTED_VALUE"""),0.0) -> 0
A27: {=XLOOKUP(D27, CountyTops!D:D, CountyTops!B:B, "")} -> Micro | C27: =IFERROR(__xludf.DUMMYFUNCTION("""COMPUTED_VALUE"""),"Columbus") -> Columbus | D27: =IFERROR(__xludf.DUMMYFUNCTION("""COMPUTED_VALUE"""),"Chattahoochee") -> Chattahoochee | I27: =IFERROR(__xludf.DUMMYFUNCTION("""COMPUTED_VALUE"""),"#DIV/0!") -> #DIV/0! | N27: =IFERROR(__xludf.DUMMYFUNCTION("""COMPUTED_VALUE"""),0.0) -> 0
A28: {=XLOOKUP(D28, CountyTops!D:D, CountyTops!B:B, "")} -> Very Small | C28: =IFERROR(__xludf.DUMMYFUNCTION("""COMPUTED_VALUE"""),"Atlanta") -> Atlanta | D28: =IFERROR(__xludf.DUMMYFUNCTION("""COMPUTED_VALUE"""),"Chattooga") -> Chattooga | I28: =IFERROR(__xludf.DUMMYFUNCTION("""COMPUTED_VALUE"""),"#DIV/0!") -> #DIV/0! | N28: =IFERROR(__xludf.DUMMYFUNCTION("""COMPUTED_VALUE"""),0.0) -> 0
A29: {=XLOOKUP(D29, CountyTops!D:D, CountyTops!B:B, "")} -> Large | C29: =IFERROR(__xludf.DUMMYFUNCTION("""COMPUTED_VALUE"""),"Atlanta") -> Atlanta | D29: =IFERROR(__xludf.DUMMYFUNCTION("""COMPUTED_VALUE"""),"Cherokee") -> Cherokee | I29: =IFERROR(__xludf.DUMMYFUNCTION("""COMPUTED_VALUE"""),"#DIV/0!") -> #DIV/0! | N29: =IFERROR(__xludf.DUMMYFUNCTION("""COMPUTED_VALUE"""),0.0) -> 0
A30: {=XLOOKUP(D30, CountyTops!D:D, CountyTops!B:B, "")} -> Small | C30: =IFERROR(__xludf.DUMMYFUNCTION("""COMPUTED_VALUE"""),"Atlanta") -> Atlanta | D30: =IFERROR(__xludf.DUMMYFUNCTION("""COMPUTED_VALUE"""),"Clarke") -> Clarke | I30: =IFERROR(__xludf.DUMMYFUNCTION("""COMPUTED_VALUE"""),"#DIV/0!") -> #DIV/0! | N30: =IFERROR(__xludf.DUMMYFUNCTION("""COMPUTED_VALUE"""),0.0) -> 0
A31: {=XLOOKUP(D31, CountyTops!D:D, CountyTops!B:B, "")} -> Micro | C31: =IFERROR(__xludf.DUMMYFUNCTION("""COMPUTED_VALUE"""),"Columbus") -> Columbus | D31: =IFERROR(__xludf.DUMMYFUNCTION("""COMPUTED_VALUE"""),"Clay") -> Clay | I31: =IFERROR(__xludf.DUMMYFUNCTION("""COMPUTED_VALUE"""),"#DIV/0!") -> #DIV/0! | N31: =IFERROR(__xludf.DUMMYFUNCTION("""COMPUTED_VALUE"""),0.0) -> 0
A32: {=XLOOKUP(D32, CountyTops!D:D, CountyTops!B:B, "")} -> Very Small | C32: =IFERROR(__xludf.DUMMYFUNCTION("""COMPUTED_VALUE"""),"Atlanta") -> Atlanta | D32: =IFERROR(__xludf.DUMMYFUNCTION("""COMPUTED_VALUE"""),"Clayton") -> Clayton | I32: =IFERROR(__xludf.DUMMYFUNCTION("""COMPUTED_VALUE"""),"#DIV/0!") -> #DIV/0! | N32: =IFERROR(__xludf.DUMMYFUNCTION("""COMPUTED_VALUE"""),0.0) -> 0
A33: {=XLOOKUP(D33, CountyTops!D:D, CountyTops!B:B, "")} -> Micro | C33: =IFERROR(__xludf.DUMMYFUNCTION("""COMPUTED_VALUE"""),"Tallahassee, FL") -> Tallahassee, FL | D33: =IFERROR(__xludf.DUMMYFUNCTION("""COMPUTED_VALUE"""),"Clinch") -> Clinch | I33: =IFERROR(__xludf.DUMMYFUNCTION("""COMPUTED_VALUE"""),"#DIV/0!") -> #DIV/0! | N33: =IFERROR(__xludf.DUMMYFUNCTION("""COMPUTED_VALUE"""),0.0) -> 0
A34: {=XLOOKUP(D34, CountyTops!D:D, CountyTops!B:B, "")} -> Mega | C34: =IFERROR(__xludf.DUMMYFUNCTION("""COMPUTED_VALUE"""),"Atlanta") -> Atlanta | D34: =IFERROR(__xludf.DUMMYFUNCTION("""COMPUTED_VALUE"""),"Cobb") -> Cobb | I34: =IFERROR(__xludf.DUMMYFUNCTION("""COMPUTED_VALUE"""),"#DIV/0!") -> #DIV/0! | N34: =IFERROR(__xludf.DUMMYFUNCTION("""COMPUTED_VALUE"""),0.0) -> 0
A35: {=XLOOKUP(D35, CountyTops!D:D, CountyTops!B:B, "")} -> Very Small | C35: =IFERROR(__xludf.DUMMYFUNCTION("""COMPUTED_VALUE"""),"Albany") -> Albany | D35: =IFERROR(__xludf.DUMMYFUNCTION("""COMPUTED_VALUE"""),"Coffee") -> Coffee | I35: =IFERROR(__xludf.DUMMYFUNCTION("""COMPUTED_VALUE"""),"#DIV/0!") -> #DIV/0! | N35: =IFERROR(__xludf.DUMMYFUNCTION("""COMPUTED_VALUE"""),0.0) -> 0
A36: {=XLOOKUP(D36, CountyTops!D:D, CountyTops!B:B, "")} -> Very Small | C36: =IFERROR(__xludf.DUMMYFUNCTION("""COMPUTED_VALUE"""),"Albany") -> Albany | D36: =IFERROR(__xludf.DUMMYFUNCTION("""COMPUTED_VALUE"""),"Colquitt") -> Colquitt | I36: =IFERROR(__xludf.DUMMYFUNCTION("""COMPUTED_VALUE"""),"#DIV/0!") -> #DIV/0! | N36: =IFERROR(__xludf.DUMMYFUNCTION("""COMPUTED_VALUE"""),0.0) -> 0
A37: {=XLOOKUP(D37, CountyTops!D:D, CountyTops!B:B, "")} -> Large | C37: =IFERROR(__xludf.DUMMYFUNCTION("""COMPUTED_VALUE"""),"Augusta") -> Augusta | D37: =IFERROR(__xludf.DUMMYFUNCTION("""COMPUTED_VALUE"""),"Columbia") -> Columbia | I37: =IFERROR(__xludf.DUMMYFUNCTION("""COMPUTED_VALUE"""),"#DIV/0!") -> #DIV/0! | N37: =IFERROR(__xludf.DUMMYFUNCTION("""COMPUTED_VALUE"""),0.0) -> 0
A38: {=XLOOKUP(D38, CountyTops!D:D, CountyTops!B:B, "")} -> Very Small | C38: =IFERROR(__xludf.DUMMYFUNCTION("""COMPUTED_VALUE"""),"Albany") -> Albany | D38: =IFERROR(__xludf.DUMMYFUNCTION("""COMPUTED_VALUE"""),"Cook") -> Cook | I38: =IFERROR(__xludf.DUMMYFUNCTION("""COMPUTED_VALUE"""),"#DIV/0!") -> #DIV/0! | N38: =IFERROR(__xludf.DUMMYFUNCTION("""COMPUTED_VALUE"""),0.0) -> 0
A39: {=XLOOKUP(D39, CountyTops!D:D, CountyTops!B:B, "")} -> Mid-Large | C39: =IFERROR(__xludf.DUMMYFUNCTION("""COMPUTED_VALUE"""),"Atlanta") -> Atlanta | D39: =IFERROR(__xludf.DUMMYFUNCTION("""COMPUTED_VALUE"""),"Coweta") -> Coweta | I39: =IFERROR(__xludf.DUMMYFUNCTION("""COMPUTED_VALUE"""),"#DIV/0!") -> #DIV/0! | N39: =IFERROR(__xludf.DUMMYFUNCTION("""COMPUTED_VALUE"""),0.0) -> 0
A40: {=XLOOKUP(D40, CountyTops!D:D, CountyTops!B:B, "")} -> Very Small | C40: =IFERROR(__xludf.DUMMYFUNCTION("""COMPUTED_VALUE"""),"Macon") -> Macon | D40: =IFERROR(__xludf.DUMMYFUNCTION("""COMPUTED_VALUE"""),"Crawford") -> Crawford | I40: =IFERROR(__xludf.DUMMYFUNCTION("""COMPUTED_VALUE"""),"#DIV/0!") -> #DIV/0! | N40: =IFERROR(__xludf.DUMMYFUNCTION("""COMPUTED_VALUE"""),0.0) -> 0
...

Sheet RegionTops
A1: DMA
B2: Average | C2: Avg % | D2: Pres Yr Avg | E2: Pres Yr Avg % | F2: Off Yr Avg | G2: Off Yr Avg % | H2: Sum of 2024 Pres Total | I2: Sum of 2022 Sen Total | J2: Sum of 2022 Gov Total | K2: Sum of 2022 Lt Gov Total | L2: Sum of 2020 Trump Total | M2: Sum of 2020 Perdue Total | N2: Sum of 2018 Gov RO Total | O2: Sum of 2018 Gov Int Total | P2: Sum of 2016 Pres Pref Total | Q2: Sum of 20216 Sen Total
A3: Albany | B3: =AVERAGE(H3:Q3) -> 37317.9 | C3: =B3/$B$15 -> 0.041016524 | D3: =AVERAGE(H3,L3,P3) -> 38937.667 | E3: =D3/$D$15 -> 0.041243698 | F3: =AVERAGE(I3,J3,K3,N3,O3) -> 36856.8 | G3: =F3/$F$15 -> 0.039244582 | H3: 23974 | I3: 46591 | J3: 47084 | K3: 43820 | L3: 43429 | M3: 44286 | N3: 21953 | O3: 24836 | P3: 49410 | Q3: 27796
A4: Atlanta | B4: =AVERAGE(H4:Q4) -> 590085.6 | C4: =B4/$B$15 -> 0.64856973 | D4: =AVERAGE(H4,L4,P4) -> 615154 | E4: =D4/$D$15 -> 0.65158568 | F4: =AVERAGE(I4,J4,K4,N4,O4) -> 613318 | G4: =F4/$F$15 -> 0.65305204 | H4: 377019 | I4: 764324 | J4: 783769 | K4: 728857 | L4: 595521 | M4: 631429 | N4: 399427 | O4: 390213 | P4: 872922 | Q4: 357375
A5: Augusta | B5: =AVERAGE(H5:Q5) -> 41810.6 | C5: =B5/$B$15 -> 0.045954501 | D5: =AVERAGE(H5,L5,P5) -> 42197.667 | E5: =D5/$D$15 -> 0.044696767 | F5: =AVERAGE(I5,J5,K5,N5,O5) -> 44182.4 | G5: =F5/$F$15 -> 0.047044773 | H5: 27782 | I5: 52990 | J5: 53821 | K5: 49967 | L5: 40975 | M5: 42660 | N5: 29802 | O5: 34332 | P5: 57836 | Q5: 27941
A6: Chattanooga | B6: =AVERAGE(H6:Q6) -> 32634.5 | C6: =B6/$B$15 -> 0.035868946 | D6: =AVERAGE(H6,L6,P6) -> 35996.667 | E6: =D6/$D$15 -> 0.038128521 | F6: =AVERAGE(I6,J6,K6,N6,O6) -> 30215.6 | G6: =F6/$F$15 -> 0.032173129 | H6: 24800 | I6: 41730 | J6: 42649 | K6: 38174 | L6: 41125 | M6: 40775 | N6: 12378 | O6: 16147 | P6: 42065 | Q6: 26502
A7: Columbus | B7: =AVERAGE(H7:Q7) -> 21146.6 | C7: =B7/$B$15 -> 0.023242466 | D7: =AVERAGE(H7,L7,P7) -> 21218.333 | E7: =D7/$D$15 -> 0.022474961 | F7: =AVERAGE(I7,J7,K7,N7,O7) -> 22517.6 | G7: =F7/$F$15 -> 0.023976411 | H7: 12916 | I7: 28053 | J7: 28664 | K7: 25726 | L7: 20549 | M7: 21590 | N7: 12389 | O7: 17756 | P7: 30190 | Q7: 13633
A8: Dothan, AL | B8: =AVERAGE(H8:Q8) -> 1154.5 | C8: =B8/$B$15 -> 0.0012689239 | D8: =AVERAGE(H8,L8,P8) -> 1105 | E8: =D8/$D$15 -> 0.0011704422 | F8: =AVERAGE(I8,J8,K8,N8,O8) -> 1186.8 | G8: =F8/$F$15 -> 0.0012636873 | H8: 720 | I8: 1421 | J8: 1432 | K8: 1316 | L8: 1241 | M8: 1417 | N8: 826 | O8: 939 | P8: 1354 | Q8: 879
A9: Greenville, SC | B9: =AVERAGE(H9:Q9) -> 13863.3 | C9: =B9/$B$15 -> 0.015237309 | D9: =AVERAGE(H9,L9,P9) -> 14380.333 | E9: =D9/$D$15 -> 0.015231989 | F9: =AVERAGE(I9,J9,K9,N9,O9) -> 13115.8 | G9: =F9/$F$15 -> 0.013965512 | H9: 10307 | I9: 16894 | J9: 17117 | K9: 15943 | L9: 17048 | M9: 17973 | N9: 6928 | O9: 8697 | P9: 15786 | Q9: 11940
A10: Jacksonville, FL | B10: =AVERAGE(H10:Q10) -> 25363 | C10: =B10/$B$15 -> 0.027876759 | D10: =AVERAGE(H10,L10,P10) -> 25508 | E10: =D10/$D$15 -> 0.027018677 | F10: =AVERAGE(I10,J10,K10,N10,O10) -> 25274 | G10: =F10/$F$15 -> 0.026911386 | H10: 17263 | I10: 32365 | J10: 32895 | K10: 29948 | L10: 28697 | M10: 29771 | N10: 13846 | O10: 17316 | P10: 30564 | Q10: 20965
A11: Macon | B11: =AVERAGE(H11:Q11) -> 61151.8 | C11: =B11/$B$15 -> 0.067212632 | D11: =AVERAGE(H11,L11,P11) -> 61384.667 | E11: =D11/$D$15 -> 0.065020092 | F11: =AVERAGE(I11,J11,K11,N11,O11) -> 65036 | G11: =F11/$F$15 -> 0.069249382 | H11: 40273 | I11: 81205 | J11: 82200 | K11: 77359 | L11: 63504 | M11: 66062 | N11: 41899 | O11: 42517 | P11: 80377 | Q11: 36122
A12: Savannah | B12: =AVERAGE(H12:Q12) -> 63581.2 | C12: =B12/$B$15 -> 0.069882813 | D12: =AVERAGE(H12,L12,P12) -> 65245.667 | E12: =D12/$D$15 -> 0.069109754 | F12: =AVERAGE(I12,J12,K12,N12,O12) -> 64216.4 | G12: =F12/$F$15 -> 0.068376684 | H12: 38773 | I12: 82812 | J12: 84500 | K12: 77765 | L12: 73003 | M12: 73952 | N12: 35776 | O12: 40229 | P12: 83961 | Q12: 45041
A13: Tallahassee, FL | B13: =AVERAGE(H13:Q13) -> 21717 | C13: =B13/$B$15 -> 0.023869399 | D13: =AVERAGE(H13,L13,P13) -> 22959.667 | E13: =D13/$D$15 -> 0.024319422 | F13: =AVERAGE(I13,J13,K13,N13,O13) -> 23237 | G13: =F13/$F$15 -> 0.024742418 | H13: 15120 | I13: 30240 | J13: 30611 | K13: 27792 | L13: 22260 | M13: 22640 | N13: 13083 | O13: 14459 | P13: 31499 | Q13: 9466
C14: =B14/$B$15 -> 0
A15: TOTAL | B15: =SUM(B3:B13) -> 909826 | C15: =SUM(C3:C13) -> 1 | D15: =SUM(D3:D13) -> 944087.67 | E15: =SUM(E3:E13) -> 1 | F15: =SUM(F3:F13) -> 939156.4 | G15: =SUM(G3:G13) -> 1 | H15: =SUM(H3:H13) -> 588947 | I15: =SUM(I3:I13) -> 1178625 | ... Q15: =SUM(Q3:Q13) -> 577660
A19: Custom Region 1
B20: Sum of Average | D20: Sum of Pres Yr Avg | F20: Sum of Off Yr Avg
A21: Athens Area | B21: 37527.2 | C21: =B21/$B$34 -> 0.041246568 | D21: 34880.8 | E21: =D21/$D$34 -> 0.039614962 | F21: 40173.6 | G21: =F21/$F$34 -> 0.042776262
A22: Augusta Area | B22: 29353.7 | C22: =B22/$B$34 -> 0.032262982 | D22: 27827.6 | E22: =D22/$D$34 -> 0.031604474 | F22: 30879.8 | G22: =F22/$F$34 -> 0.032880359
A23: Coastal GA | B23: 48244.8 | C23: =B23/$B$34 -> 0.053026403 | D23: 45572.4 | E23: =D23/$D$34 -> 0.051757669 | F23: 50917.2 | G23: =F23/$F$34 -> 0.05421589
A24: Columbus/Phenix | B24: 15420 | C24: =B24/$B$34 -> 0.016948296 | D24: 14210.6 | E24: =D24/$D$34 -> 0.01613932 | F24: 16629.4 | G24: =F24/$F$34 -> 0.017706742
A25: Greater Metro Atlanta | B25: 170444.7 | C25: =B25/$B$34 -> 0.18733769 | D25: 162896 | E25: =D25/$D$34 -> 0.1850049 | F25: 177993.4 | G25: =F25/$F$34 -> 0.18952477
A26: Macon Metro | B26: 39936.6 | C26: =B26/$B$34 -> 0.043894767 | D26: 37339.6 | E26: =D26/$D$34 -> 0.042407481 | F26: 42533.6 | G26: =F26/$F$34 -> 0.045289155
A27: Metro Atlanta | B27: 196661.9 | C27: =B27/$B$34 -> 0.21615331 | D27: 183546.6 | E27: =D27/$D$34 -> 0.20845828 | F27: 209777.2 | G27: =F27/$F$34 -> 0.22336769
A28: Middle GA | B28: 94936.6 | C28: =B28/$B$34 -> 0.10434589 | D28: 92615.2 | E28: =D28/$D$34 -> 0.10518531 | F28: 97258 | G28: =F28/$F$34 -> 0.1035589
A29: N GA | B29: 90844.7 | C29: =B29/$B$34 -> 0.099848433 | D29: 90278.6 | E29: =D29/$D$34 -> 0.10253157 | F29: 91410.8 | G29: =F29/$F$34 -> 0.097332883
A30: NW GA | B30: 65899.3 | C30: =B30/$B$34 -> 0.072430663 | D30: 69235.4 | E30: =D30/$D$34 -> 0.078632307 | F30: 62563.2 | G30: =F30/$F$34 -> 0.06661638
A31: S GA | B31: 110452.3 | C31: =B31/$B$34 -> 0.12139937 | D31: 111444.6 | E31: =D31/$D$34 -> 0.12657031 | F31: 109460 | G31: =F31/$F$34 -> 0.11655141
A32: West GA | B32: 10104.2 | C32: =B32/$B$34 -> 0.01110564 | D32: 10648.2 | E32: =D32/$D$34 -> 0.012093416 | F32: 9560.2 | G32: =F32/$F$34 -> 0.010179561
A34: Grand Total | B34: 909826 | C34: =B34/$B$34 -> 1 | D34: 880495.6 | E34: =D34/$D$34 -> 1 | F34: 939156.4 | G34: =F34/$F$34 -> 1
A38: Custom Region 2
B39: Sum of Average | D39: Sum of Pres Yr Avg | F39: Sum of Off Yr Avg | I39: Total Counties | J39: Avg/County By Off Yr Avg | L39: 22 GOP Primary i360 Ind | M39: HH | N39: Total Phone | O39: Cells | R39: =SUM(R40:R44) -> 49
A40: Mega | B40: 170050.6 | C40: =B40/$B$48 -> 0.18690453 | D40: 158307 | E40: =D40/$D$48 -> 0.17979306 | F40: 181794.2 | G40: =F40/$F$48 -> 0.19357181 | I40: 3 | J40: 60598.067 | L40: 70032 | M40: 47011.667 | N40: 64074 | O40: 53953.667 | Q40: 3 | R40: 9
A41: Large | B41: 132533.5 | C41: =B41/$B$48 -> 0.14566906 | D41: 123822.8 | E41: =D41/$D$48 -> 0.14062853 | F41: 141244.2 | G41: =F41/$F$48 -> 0.15039476 | I41: 5 | J41: 28248.84 | L41: 34363 | M41: 22679 | N41: 30647.4 | O41: 25639 | Q41: 2 | R41: 10
A42: Mid-Large | B42: 86418.6 | C42: =B42/$B$48 -> 0.094983656 | D42: 82500.4 | E42: =D42/$D$48 -> 0.093697686 | F42: 90336.8 | G42: =F42/$F$48 -> 0.096189304 | I42: 5 | J42: 18067.36 | L42: 21368 | M42: 14085.6 | N42: 18828.8 | O42: 15212.2 | Q42: 2 | R42: 10
A43: Mid-Small | B43: 115941.7 | C43: =B43/$B$48 -> 0.12743283 | D43: 111765.6 | E43: =D43/$D$48 -> 0.12693488 | F43: 120117.8 | G43: =F43/$F$48 -> 0.12789968 | I43: 10 | J43: 12011.78 | L43: 14723 | M43: 9853.3 | N43: 12967.5 | O43: 10310.5 | Q43: 1 | R43: 10
A44: Small | B44: 179600.3 | C44: =B44/$B$48 -> 0.19740071 | D44: 178306.4 | E44: =D44/$D$48 -> 0.20250686 | F44: 180894.2 | G44: =F44/$F$48 -> 0.1926135 | I44: 27 | J44: 6699.7852 | L44: 8215 | M44: 5473.9259 | N44: 7216.8519 | O44: 5667.5926 | R44: 10
A45: Very Small | B45: 209092.6 | C45: =B45/$B$48 -> 0.22981603 | D45: 211002.2 | E45: =D45/$D$48 -> 0.23964027 | F45: 207183 | G45: =F45/$F$48 -> 0.22060543 | I45: 80 | J45: 2589.7875 | L45: 3200 | M45: 2147.525 | N45: 2714.9375 | O45: 2012.4125
A46: Micro | B46: 16188.7 | C46: =B46/$B$48 -> 0.017793182 | D46: 14791.2 | E46: =D46/$D$48 -> 0.016798721 | F46: 17586.2 | G46: =F46/$F$48 -> 0.018725529 | I46: 29 | J46: 606.42069 | L46: 730 | M46: 501.03448 | N46: 585.58621 | O46: 403.06897
A48: Grand Total | B48: 909826 | C48: =B48/$B$48 -> 1 | D48: 880495.6 | E48: =D48/$D$48 -> 1 | F48: 939156.4 | G48: =F48/$F$48 -> 1

Sheet CountyTops
M3: 2024 Pres | O3: 2022 US Sen | Q3: 2022 Gov | S3: 2022 Lt Gov | U3: 2020 Pres | W3: 2020 US Sen | Y3: 2018 Gov RO | AA3: 2018 Gov Int. | AC3: 2016 Pres Pref. | AE3: 2016 US Sen
E4: =SUM(E6:E164) -> 909826 | F4: =SUM(F6:F164) -> 1 | G4: =SUM(G6:G164) -> 880495.6 | H4: =SUM(H6:H164) -> 1 | I4: =SUM(I6:I164) -> 939156.4 | J4: =SUM(J6:J164) -> 1 | K4: =SUM(K6:K164) -> 1166678 | L4: =SUM(L6:L164) -> 1 | ... AF4: =SUM(AF6:AF164) -> 1.0565914 | AH4: 2022 Primary (i360)
A5: Custom Geo I | B5: Custom Geo II | C5: DMA | D5: County | E5: Average | F5: Avg % | G5: Pres Yr Avg | H5: Pres Yr Avg % | I5: Off Yr Avg | J5: Off Yr Avg % | K5: 2022 Avg | L5: 2022 Avg % | M5: Total | N5: % Cont. | O5: Total | P5: % Cont. | Q5: Total | R5: % Cont. | S5: Total | T5: % Cont. | U5: Trump Total | V5: % Cont. | W5: Perdue Total | X5: % Cont. | Y5: Total | Z5: % Cont. | AA5: Total | AB5: % Cont. | AC5: Total | AD5: % Cont. | AE5: Total | AF5: % Cont. | AG5: Individuals | AH5: Mailing Addresses | AI5: Total Phones (LL + Cell) | AJ5: Cells
A6: Metro Atlanta | B6: Mega | C6: Atlanta | D6: Cobb | E6: =AVERAGE(M6,O6,Q6,S6,U6,W6,Y6,AA6,AC6,AE6) -> 67850.6 | F6: =E6/$E$4 -> 0.074575358 | G6: =AVERAGE(M6,U6,W6,AC6,AE6) -> 63917 | H6: =G6/$G$4 -> 0.072592072 | I6: =AVERAGE(O6,Q6,S6,Y6,AA6) -> 71784.2 | J6: =I6/$I$4 -> 0.076434766 | K6: =AVERAGE(O6,Q6,S6) -> 89225 | L6: =K6/$K$4 -> 0.076477828 | M6: 39947 | N6: =M6/$M$4 -> 0.067827835 | O6: 90018 | P6: =O6/$O$4 -> 0.076375437 | Q6: 92923 | R6: =Q6/$Q$4 -> 0.077131037 | S6: 84734 | T6: =S6/$S$4 -> 0.075881171 | U6: 63696 | V6: =U6/$U$4 -> 0.067235832 | W6: 67252 | X6: =W6/$W$4 -> 0.067756447 | Y6: 49527 | Z6: =Y6/$Y$4 -> 0.084185638 | AA6: 41719 | AB6: =AA6/$AA$4 -> 0.068679921 | AC6: 112197 | AD6: =AC6/$AC$4 -> 0.086574164 | AE6: 36493 | AF6: =AE6/$AE$4 -> 0.063173839 | AG6: 83977 | AH6: 54927 | AI6: 76807 | AJ6: 64497
A7: Metro Atlanta | B7: Mega | C7: Atlanta | D7: Gwinnett | E7: =AVERAGE(M7,O7,Q7,S7,U7,W7,Y7,AA7,AC7,AE7) -> 54995.7 | F7: =E7/$E$4 -> 0.060446393 | G7: =AVERAGE(M7,U7,W7,AC7,AE7) -> 53770.2 | H7: =G7/$G$4 -> 0.061068108 | I7: =AVERAGE(O7,Q7,S7,Y7,AA7) -> 56221.2 | J7: =I7/$I$4 -> 0.059863512 | K7: =AVERAGE(O7,Q7,S7) -> 68183.667 | L7: =K7/$K$4 -> 0.058442575 | M7: 29075 | N7: =M7/$M$4 -> 0.04936777 | O7: 68504 | P7: =O7/$O$4 -> 0.058121964 | Q7: 70227 | R7: =Q7/$Q$4 -> 0.058292149 | S7: 65820 | T7: =S7/$S$4 -> 0.058943266 | U7: 57897 | V7: =U7/$U$4 -> 0.061114559 | W7: 60783 | X7: =W7/$W$4 -> 0.061238924 | Y7: 40312 | Z7: =Y7/$Y$4 -> 0.068522047 | AA7: 36243 | AB7: =AA7/$AA$4 -> 0.059665054 | AC7: 98949 | AD7: =AC7/$AC$4 -> 0.076351658 | AE7: 22147 | AF7: =AE7/$AE$4 -> 0.038339161 | AG7: 61667 | AH7: 41495 | AI7: 56484 | AJ7: 47348
A8: Metro Atlanta | B8: Mega | C8: Atlanta | D8: Fulton | E8: =AVERAGE(M8,O8,Q8,S8,U8,W8,Y8,AA8,AC8,AE8) -> 47204.3 | F8: =E8/$E$4 -> 0.051882778 | G8: =AVERAGE(M8,U8,W8,AC8,AE8) -> 40619.8 | H8: =G8/$G$4 -> 0.046132882 | I8: =AVERAGE(O8,Q8,S8,Y8,AA8) -> 53788.8 | J8: =I8/$I$4 -> 0.057273528 | K8: =AVERAGE(O8,Q8,S8) -> 66236 | L8: =K8/$K$4 -> 0.056773163 | M8: 27400 | N8: =M8/$M$4 -> 0.046523711 | O8: 67075 | P8: =O8/$O$4 -> 0.056909534 | Q8: 69796 | R8: =Q8/$Q$4 -> 0.057934396 | S8: 61837 | T8: =S8/$S$4 -> 0.055376401 | U8: 33861 | V8: =U8/$U$4 -> 0.035742786 | W8: 37579 | X8: =W8/$W$4 -> 0.037860874 | Y8: 35081 | Z8: =Y8/$Y$4 -> 0.059630431 | AA8: 35155 | AB8: =AA8/$AA$4 -> 0.057873933 | AC8: 84794 | AD8: =AC8/$AC$4 -> 0.065429287 | AE8: 19465 | AF8: =AE8/$AE$4 -> 0.033696292 | AG8: 64451 | AH8: 44613 | AI8: 58931 | AJ8: 50016
A9: Greater Metro Atlanta | B9: Large | C9: Atlanta | D9: Cherokee | E9: =AVERAGE(M9,O9,Q9,S9,U9,W9,Y9,AA9,AC9,AE9) -> 36394.2 | F9: =E9/$E$4 -> 0.040001275 | G9: =AVERAGE(M9,U9,W9,AC9,AE9) -> 34205 | H9: =G9/$G$4 -> 0.03884744 | I9: =AVERAGE(O9,Q9,S9,Y9,AA9) -> 38583.4 | J9: =I9/$I$4 -> 0.04108304 | K9: =AVERAGE(O9,Q9,S9) -> 50427.667 | L9: =K9/$K$4 -> 0.043223294 | M9: 26317 | N9: =M9/$M$4 -> 0.044684836 | O9: 50700 | P9: =O9/$O$4 -> 0.043016227 | Q9: 52199 | R9: =Q9/$Q$4 -> 0.043327949 | S9: 48384 | T9: =S9/$S$4 -> 0.043328942 | U9: 35457 | V9: =U9/$U$4 -> 0.037427482 | W9: 37450 | X9: =W9/$W$4 -> 0.037730907 | Y9: 20646 | Z9: =Y9/$Y$4 -> 0.035093922 | AA9: 20988 | AB9: =AA9/$AA$4 -> 0.034551504 | AC9: 50327 | AD9: =AC9/$AC$4 -> 0.03883364 | AE9: 21474 | AF9: =AE9/$AE$4 -> 0.037174116 | AG9: 51300 | AH9: 33370 | AI9: 45812 | AJ9: 39190
A10: Greater Metro Atlanta | B10: Large | C10: Atlanta | D10: Forsyth | E10: =AVERAGE(M10,O10,Q10,S10,U10,W10,Y10,AA10,AC10,AE10) -> 30326.3 | F10: =E10/$E$4 -> 0.033331978 | G10: =AVERAGE(M10,U10,W10,AC10,AE10) -> 28044.6 | H10: =G10/$G$4 -> 0.031850926 | I10: =AVERAGE(O10,Q10,S10,Y10,AA10) -> 32608 | J10: =I10/$I$4 -> 0.034720522 | K10: =AVERAGE(O10,Q10,S10) -> 39320.667 | L10: =K10/$K$4 -> 0.033703101 | M10: 19736 | N10: =M10/$M$4 -> 0.033510655 | O10: 39491 | P10: =O10/$O$4 -> 0.033505992 | Q10: 40466 | R10: =Q10/$Q$4 -> 0.033588934 | S10: 38005 | T10: =S10/$S$4 -> 0.034034318 | U10: 28848 | V10: =U10/$U$4 -> 0.030451194 | W10: 30884 | X10: =W10/$W$4 -> 0.031115656 | Y10: 19475 | Z10: =Y10/$Y$4 -> 0.033103465 | AA10: 25603 | AB10: =AA10/$AA$4 -> 0.042148949 | AC10: 42318 | AD10: =AC10/$AC$4 -> 0.032653685 | AE10: 18437 | AF10: =AE10/$AE$4 -> 0.031916698 | AG10: 37710 | AH10: 24264 | AI10: 33866 | AJ10: 29071
A11: N GA | B11: Large | C11: Atlanta | D11: Hall | E11: =AVERAGE(M11,O11,Q11,S11,U11,W11,Y11,AA11,AC11,AE11) -> 24588.3 | F11: =E11/$E$4 -> 0.027025277 | G11: =AVERAGE(M11,U11,W11,AC11,AE11) -> 22999.6 | H11: =G11/$G$4 -> 0.026121198 | I11: =AVERAGE(O11,Q11,S11,Y11,AA11) -> 26177 | J11: =I11/$I$4 -> 0.027872887 | K11: =AVERAGE(O11,Q11,S11) -> 32187.333 | L11: =K11/$K$4 -> 0.027588875 | M11: 16864 | N11: =M11/$M$4 -> 0.028634156 | O11: 32129 | P11: =O11/$O$4 -> 0.027259731 | Q11: 32620 | R11: =Q11/$Q$4 -> 0.027076337 | S11: 31813 | T11: =S11/$S$4 -> 0.028489245 | U11: 26186 | V11: =U11/$U$4 -> 0.027641257 | W11: 27725 | X11: =W11/$W$4 -> 0.027932961 | Y11: 18823 | Z11: =Y11/$Y$4 -> 0.0319952 | AA11: 15500 | AB11: =AA11/$AA$4 -> 0.025516881 | AC11: 32623 | AD11: =AC11/$AC$4 -> 0.025172767 | AE11: 11600 | AF11: =AE11/$AE$4 -> 0.020081017 | AG11: 31654 | AH11: 20449 | AI11: 27985 | AJ11: 23240
A12: Metro Atlanta | B12: Large | C12: Atlanta | D12: DeKalb | E12: =AVERAGE(M12,O12,Q12,S12,U12,W12,Y12,AA12,AC12,AE12) -> 22326.8 | F12: =E12/$E$4 -> 0.024539637 | G12: =AVERAGE(M12,U12,W12,AC12,AE12) -> 20893.8 | H12: =G12/$G$4 -> 0.02372959 | I12: =AVERAGE(O12,Q12,S12,Y12,AA12) -> 23759.8 | J12: =I12/$I$4 -> 0.025299088 | K12: =AVERAGE(O12,Q12,S12) -> 29072 | L12: =K12/$K$4 -> 0.024918615 | M12: 12595 | N12: =M12/$M$4 -> 0.021385626 | O12: 29395 | P12: =O12/$O$4 -> 0.024940078 | Q12: 30685 | R12: =Q12/$Q$4 -> 0.025470184 | S12: 27136 | T12: =S12/$S$4 -> 0.024300888 | U12: 17425 | V12: =U12/$U$4 -> 0.018393374 | W12: 18923 | X12: =W12/$W$4 -> 0.019064938 | Y12: 16498 | Z12: =Y12/$Y$4 -> 0.028043182 | AA12: 15085 | AB12: =AA12/$AA$4 -> 0.024833688 | AC12: 44450 | AD12: =AC12/$AC$4 -> 0.034298792 | AE12: 11076 | AF12: =AE12/$AE$4 -> 0.019173909 | AG12: 28258 | AH12: 20438 | AI12: 26134 | AJ12: 21407
A13: Augusta Area | B13: Large | C13: Augusta | D13: Columbia | E13: =AVERAGE(M13,O13,Q13,S13,U13,W13,Y13,AA13,AC13,AE13) -> 18897.9 | F13: =E13/$E$4 -> 0.020770895 | G13: =AVERAGE(M13,U13,W13,AC13,AE13) -> 17679.8 | H13: =G13/$G$4 -> 0.020079373 | I13: =AVERAGE(O13,Q13,S13,Y13,AA13) -> 20116 | J13: =I13/$I$4 -> 0.021419223 | K13: =AVERAGE(O13,Q13,S13) -> 23315.667 | L13: =K13/$K$4 -> 0.019984663 | M13: 13437 | N13: =M13/$M$4 -> 0.022815296 | O13: 23595 | P13: =O13/$O$4 -> 0.02001909 | Q13: 24011 | R13: =Q13/$Q$4 -> 0.019930408 | S13: 22341 | T13: =S13/$S$4 -> 0.02000686 | U13: 17358 | V13: =U13/$U$4 -> 0.018322651 | W13: 18509 | X13: =W13/$W$4 -> 0.018647833 | Y13: 15530 | Z13: =Y13/$Y$4 -> 0.026397782 | AA13: 15103 | AB13: =AA13/$AA$4 -> 0.02486332 | AC13: 26505 | AD13: =AC13/$AC$4 -> 0.020451957 | AE13: 12590 | AF13: =AE13/$AE$4 -> 0.021794827 | AG13: 22892 | AH13: 14874 | AI13: 19440 | AJ13: 15287
A14: Coastal GA | B14: Mid-Large | C14: Savannah | D14: Chatham | E14: =AVERAGE(M14,O14,Q14,S14,U14,W14,Y14,AA14,AC14,AE14) -> 18257.1 | F14: =E14/$E$4 -> 0.020066584 | G14: =AVERAGE(M14,U14,W14,AC14,AE14) -> 16762.4 | H14: =G14/$G$4 -> 0.01903746 | I14: =AVERAGE(O14,Q14,S14,Y14,AA14) -> 19751.8 | J14: =I14/$I$4 -> 0.021031428 | K14: =AVERAGE(O14,Q14,S14) -> 25138.667 | L14: =K14/$K$4 -> 0.021547219 | M14: 10055 | N14: =M14/$M$4 -> 0.017072844 | O14: 25455 | P14: =O14/$O$4 -> 0.0215972 | Q14: 26113 | R14: =Q14/$Q$4 -> 0.02167518 | S14: 23848 | T14: =S14/$S$4 -> 0.021356412 | U14: 18680 | V14: =U14/$U$4 -> 0.01971812 | W14: 19461 | X14: =W14/$W$4 -> 0.019606974 | Y14: 11949 | Z14: =Y14/$Y$4 -> 0.020310824 | AA14: 11394 | AB14: =AA14/$AA$4 -> 0.018757377 | AC14: 30671 | AD14: =AC14/$AC$4 -> 0.023666552 | AE14: 4945 | AF14: =AE14/$AE$4 -> 0.0085603989 | AG14: 24415 | AH14: 16957 | AI14: 20970 | AJ14: 16663
A15: Greater Metro Atlanta | B15: Mid-Large | C15: Atlanta | D15: Coweta | E15: =AVERAGE(M15,O15,Q15,S15,U15,W15,Y15,AA15,AC15,AE15) -> 17804.8 | F15: =E15/$E$4 -> 0.019569456 | G15: =AVERAGE(M15,U15,W15,AC15,AE15) -> 16351 | H15: =G15/$G$4 -> 0.018570223 | I15: =AVERAGE(O15,Q15,S15,Y15,AA15) -> 19258.6 | J15: =I15/$I$4 -> 0.020506276 | K15: =AVERAGE(O15,Q15,S15) -> 25115.333 | L15: =K15/$K$4 -> 0.021527219 | M15: 11288 | N15: =M15/$M$4 -> 0.019166411 | O15: 25362 | P15: =O15/$O$4 -> 0.021518295 | Q15: 25974 | R15: =Q15/$Q$4 -> 0.021559803 | S15: 24010 | T15: =S15/$S$4 -> 0.021501486 | U15: 17274 | V15: =U15/$U$4 -> 0.018233983 | W15: 18333 | X15: =W15/$W$4 -> 0.018470513 | Y15: 10485 | Z15: =Y15/$Y$4 -> 0.017822327 | AA15: 10462 | AB15: =AA15/$AA$4 -> 0.017223072 | AC15: 25333 | AD15: =AC15/$AC$4 -> 0.019547611 | AE15: 9527 | AF15: =AE15/$AE$4 -> 0.0164924 | AG15: 25132 | AH15: 15981 | AI15: 21805 | AJ15: 17476
A16: Greater Metro Atlanta | B16: Mid-Large | C16: Atlanta | D16: Paulding | E16: =AVERAGE(M16,O16,Q16,S16,U16,W16,Y16,AA16,AC16,AE16) -> 17306.2 | F16: =E16/$E$4 -> 0.019021439 | G16: =AVERAGE(M16,U16,W16,AC16,AE16) -> 17064 | H16: =G16/$G$4 -> 0.019379995 | I16: =AVERAGE(O16,Q16,S16,Y16,AA16) -> 17548.4 | J16: =I16/$I$4 -> 0.01868528 | K16: =AVERAGE(O16,Q16,S16) -> 21474.667 | L16: =K16/$K$4 -> 0.018406678 | M16: 11562 | N16: =M16/$M$4 -> 0.019631648 | O16: 21629 | P16: =O16/$O$4 -> 0.018351045 | Q16: 22072 | R16: =Q16/$Q$4 -> 0.018320935 | S16: 20723 | T16: =S16/$S$4 -> 0.018557905 | U16: 19958 | V16: =U16/$U$4 -> 0.021067143 | W16: 21062 | X16: =W16/$W$4 -> 0.021219983 | Y16: 12117 | Z16: =Y16/$Y$4 -> 0.020596389 | AA16: 11201 | AB16: =AA16/$AA$4 -> 0.018439651 | AC16: 24177 | AD16: =AC16/$AC$4 -> 0.018655611 | AE16: 8561 | AF16: =AE16/$AE$4 -> 0.014820136 | AG16: 20367 | AH16: 13476 | AI16: 18040 | AJ16: 15362
A17: Greater Metro Atlanta | B17: Mid-Large | C17: Atlanta | D17: Henry | E17: =AVERAGE(M17,O17,Q17,S17,U17,W17,Y17,AA17,AC17,AE17) -> 17008.4 | F17: =E17/$E$4 -> 0.018694124 | G17: =AVERAGE(M17,U17,W17,AC17,AE17) -> 16701 | H17: =G17/$G$4 -> 0.018967727 | I17: =AVERAGE(O17,Q17,S17,Y17,AA17) -> 17315.8 | J17: =I17/$I$4 -> 0.018437611 | K17: =AVERAGE(O17,Q17,S17) -> 19646.667 | L17: =K17/$K$4 -> 0.016839836 | M17: 9196 | N17: =M17/$M$4 -> 0.015614308 | O17: 19697 | P17: =O17/$O$4 -> 0.016711846 | Q17: 20117 | R17: =Q17/$Q$4 -> 0.016698181 | S17: 19126 | T17: =S17/$S$4 -> 0.017127756 | U17: 17417 | V17: =U17/$U$4 -> 0.01838493 | W17: 18712 | X17: =W17/$W$4 -> 0.018852356 | Y17: 14637 | Z17: =Y17/$Y$4 -> 0.024879867 | AA17: 13002 | AB17: =AA17/$AA$4 -> 0.021404548 | AC17: 28289 | AD17: =AC17/$AC$4 -> 0.021828538 | AE17: 9891 | AF17: =AE17/$AE$4 -> 0.017122529 | AG17: 17423 | AH17: 11560 | AI17: 15922 | AJ17: 12865
... A97: S GA | B97: Very Small | C97: Savannah | D97: Tattnall | E97: =AVERAGE(M97,O97,Q97,S97,U97,W97,Y97,AA97,AC97,AE97) -> 2462.3 | F97: =E97/$E$4 -> 0.0027063417 | G97: =AVERAGE(M97,U97,W97,AC97,AE97) -> 2550 | H97: =G97/$G$4 -> 0.0028960962 | I97: =AVERAGE(O97,Q97,S97,Y97,AA97) -> 2374.6 | J97: =I97/$I$4 -> 0.0025284394 | K97: =AVERAGE(O97,Q97,S97) -> 2965.3333 | L97: =K97/$K$4 -> 0.0025416896 | M97: 1449 | N97: =M97/$M$4 -> 0.0024603233 | O97: 3014 | P97: =O97/$O$4 -> 0.0025572171 | Q97: 3059 | R97: =Q97/$Q$4 -> 0.0025391329 | S97: 2823 | T97: =S97/$S$4 -> 0.0025280589 | U97: 3350 | V97: =U97/$U$4 -> 0.0035361724 | W97: 3188 | X97: =W97/$W$4 -> 0.0032119127 | Y97: 1298 | Z97: =Y97/$Y$4 -> 0.002206331 | AA97: 1679 | AB97: =AA97/$AA$4 -> 0.0027640545 | AC97: 2558 | AD97: =AC97/$AC$4 -> 0.0019738203 | AE97: 2205 | AF97: =AE97/$AE$4 -> 0.0038171243 | AG97: 2875 | AH97: 1961 | AI97: 2318 | AJ97: 1638
A98: NW GA | B98: Very Small | C98: Chattanooga | D98: Dade | E98: =AVERAGE(M98,O98,Q98,S98,U98,W98,Y98,AA98,AC98,AE98) -> 2449.2 | F98: =E98/$E$4 -> 0.0026919433 | G98: =AVERAGE(M98,U98,W98,AC98,AE98) -> 2502.4 | H98: =G98/$G$4 -> 0.0028420358 | I98: =AVERAGE(O98,Q98,S98,Y98,AA98) -> 2396 | J98: =I98/$I$4 -> 0.0025512258 | K98: =AVERAGE(O98,Q98,S98) -> 2981.6667 | L98: =K98/$K$4 -> 0.0025556895 | M98: 1746 | N98: =M98/$M$4 -> 0.0029646131 | O98: 3069 | P98: =O98/$O$4 -> 0.0026038816 | Q98: 3169 | R98: =Q98/$Q$4 -> 0.0026304387 | S98: 2707 | T98: =S98/$S$4 -> 0.0024241784 | U98: 3070 | V98: =U98/$U$4 -> 0.0032406117 | W98: 2932 | X98: =W98/$W$4 -> 0.0029539925 | Y98: 1037 | Z98: =Y98/$Y$4 -> 0.0017626851 | AA98: 1998 | AB98: =AA98/$AA$4 -> 0.0032892083 | AC98: 2795 | AD98: =AC98/$AC$4 -> 0.0021566957 | AE98: 1969 | AF98: 0.06 | AG98: 3056 | AH98: 2050 | AI98: 2416 | AJ98: 1904
A99: S GA | B99: Very Small | C99: Columbus | D99: Sumter | E99: =AVERAGE(M99,O99,Q99,S99,U99,W99,Y99,AA99,AC99,AE99) -> 2422.1 | F99: =E99/$E$4 -> 0.0026621574 | G99: =AVERAGE(M99,U99,W99,AC99,AE99) -> 2513 | H99: =G99/$G$4 -> 0.0028540745 | I99: =AVERAGE(O99,Q99,S99,Y99,AA99) -> 2331.2 | J99: =I99/$I$4 -> 0.0024822277 | K99: =AVERAGE(O99,Q99,S99) -> 2842.6667 | L99: =K99/$K$4 -> 0.0024365478 | M99: 1356 | N99: =M99/$M$4 -> 0.0023024143 | O99: 2918 | P99: =O99/$O$4 -> 0.0024757663 | Q99: 2946 | R99: =Q99/$Q$4 -> 0.0024453368 | S99: 2664 | T99: =S99/$S$4 -> 0.0023856709 | U99: 2449 | V99: =U99/$U$4 -> 0.0025851004 | W99: 2495 | X99: =W99/$W$4 -> 0.0025137146 | Y99: 1332 | Z99: =Y99/$Y$4 -> 0.002264124 | AA99: 1796 | AB99: =AA99/$AA$4 -> 0.0029566657 | AC99: 3010 | AD99: =AC99/$AC$4 -> 0.0023225954 | AE99: 3255 | AF99: =AE99/$AE$4 -> 0.0056348025 | AG99: 2771 | AH99: 1878 | AI99: 2251 | AJ99: 1460
A100: Middle GA | B100: Very Small | C100: Atlanta | D100: Lamar | E100: =AVERAGE(M100,O100,Q100,S100,U100,W100,Y100,AA100,AC100,AE100) -> 2406.4 | F100: =E100/$E$4 -> 0.0026449013 | G100: =AVERAGE(M100,U100,W100,AC100,AE100) -> 2240.6 | H100: =G100/$G$4 -> 0.0025447032 | I100: =AVERAGE(O100,Q100,S100,Y100,AA100) -> 2572.2 | J100: =I100/$I$4 -> 0.0027388409 | K100: =AVERAGE(O100,Q100,S100) -> 3226.6667 | L100: =K100/$K$4 -> 0.0027656874 | M100: 1684 | N100: =M100/$M$4 -> 0.0028593405 | O100: 3222 | P100: =O100/$O$4 -> 0.0027336939 | Q100: 3295 | R100: =Q100/$Q$4 -> 0.0027350254 | S100: 3163 | T100: =S100/$S$4 -> 0.0028325365 | U100: 2490 | V100: =U100/$U$4 -> 0.0026283789 | W100: 2645 | X100: =W100/$W$4 -> 0.0026648397 | Y100: 1645 | Z100: =Y100/$Y$4 -> 0.0027961591 | AA100: 1536 | AB100: =AA100/$AA$4 -> 0.0025286406 | AC100: 3075 | AD100: =AC100/$AC$4 -> 0.0023727511 | AE100: 1309 | AF100: =AE100/$AE$4 -> 0.0022660388 | AG100: 3272 | AH100: 2136 | AI100: 2829 | AJ100: 2188
A101: Middle GA | B101: Very Small | C101: Augusta | D101: McDuffie | E101: =AVERAGE(M101,O101,Q101,S101,U101,W101,Y101,AA101,AC101,AE101) -> 2391.9 | F101: =E101/$E$4 -> 0.0026289642 | G101: =AVERAGE(M101,U101,W101,AC101,AE101) -> 2377 | H101: =G101/$G$4 -> 0.002699616 | I101: =AVERAGE(O101,Q101,S101,Y101,AA101) -> 2406.8 | J101: =I101/$I$4 -> 0.0025627254 | K101: =AVERAGE(O101,Q101,S101) -> 3021.6667 | L101: =K101/$K$4 -> 0.0025899748 | M101: 1748 | N101: =M101/$M$4 -> 0.002968009 | O101: 3048 | P101: =O101/$O$4 -> 0.0025860643 | Q101: 3074 | R101: =Q101/$Q$4 -> 0.0025515837 | S101: 2943 | T101: =S101/$S$4 -> 0.0026355216 | U101: 2068 | V101: =U101/$U$4 -> 0.0021829267 | W101: 2454 | X101: =W101/$W$4 -> 0.0024724071 | Y101: 1528 | Z101: =Y101/$Y$4 -> 0.0025972834 | AA101: 1441 | AB101: =AA101/$AA$4 -> 0.0023722469 | AC101: 3168 | AD101: =AC101/$AC$4 -> 0.0024445123 | AE101: 2447 | AF101: =AE101/$AE$4 -> 0.0042360558 | AG101: 2962 | AH101: 2029 | AI101: 2507 | AJ101: 1856
A102: Macon Metro | B102: Very Small | C102: Macon | D102: Peach | E102: =AVERAGE(M102,O102,Q102,S102,U102,W102,Y102,AA102,AC102,AE102) -> 2202.1 | F102: =E102/$E$4 -> 0.0024203529 | G102: =AVERAGE(M102,U102,W102,AC102,AE102) -> 2024 | H102: =G102/$G$4 -> 0.0022987054 | I102: =AVERAGE(O102,Q102,S102,Y102,AA102) -> 2380.2 | J102: =I102/$I$4 -> 0.0025344022 | K102: =AVERAGE(O102,Q102,S102) -> 2990.3333 | L102: =K102/$K$4 -> 0.002563118 | M102: 1542 | N102: =M102/$M$4 -> 0.0026182322 | O102: 3022 | P102: =O102/$O$4 -> 0.0025640047 | Q102: 3066 | R102: =Q102/$Q$4 -> 0.0025449432 | S102: 2883 | T102: =S102/$S$4 -> 0.0025817903 | U102: 2068 | V102: =U102/$U$4 -> 0.0021829267 | W102: 2240 | X102: =W102/$W$4 -> 0.0022568019 | Y102: 1477 | Z102: =Y102/$Y$4 -> 0.002510594 | AA102: 1453 | AB102: =AA102/$AA$4 -> 0.0023920019 | AC102: 3052 | AD102: =AC102/$AC$4 -> 0.0023550037 | AE102: 1218 | AF102: =AE102/$AE$4 -> 0.0021085067 | AG102: 2936 | AH102: 1954 | AI102: 2601 | AJ102: 1982
A103: Middle GA | B103: Very Small | C103: Atlanta | D103: Jasper | E103: =AVERAGE(M103,O103,Q103,S103,U103,W103,Y103,AA103,AC103,AE103) -> 2193.8 | F103: =E103/$E$4 -> 0.0024112303 | G103: =AVERAGE(M103,U103,W103,AC103,AE103) -> 2043.6 | H103: =G103/$G$4 -> 0.0023209656 | I103: =AVERAGE(O103,Q103,S103,Y103,AA103) -> 2344 | J103: =I103/$I$4 -> 0.0024958569 | K103: =AVERAGE(O103,Q103,S103) -> 2954 | L103: =K103/$K$4 -> 0.0025319754 | M103: 1847 | N103: =M103/$M$4 -> 0.0031361056 | O103: 2946 | P103: =O103/$O$4 -> 0.0024995227 | Q103: 2982 | R103: =Q103/$Q$4 -> 0.0024752188 | S103: 2934 | T103: =S103/$S$4 -> 0.0026274619 | U103: 2289 | V103: =U103/$U$4 -> 0.0024162085 | W103: 2436 | X103: =W103/$W$4 -> 0.0024542721 | Y103: 1502 | Z103: =Y103/$Y$4 -> 0.0025530888 | AA103: 1356 | AB103: =AA103/$AA$4 -> 0.0022323156 | AC103: 2499 | AD103: =AC103/$AC$4 -> 0.0019282943 | AE103: 1147 | AF103: =AE103/$AE$4 -> 0.0019855971 | AG103: 3079 | AH103: 2020 | AI103: 2681 | AJ103: 2149
A104: S GA | B104: Very Small | C104: Albany | D104: Crisp | E104: =AVERAGE(M104,O104,Q104,S104,U104,W104,Y104,AA104,AC104,AE104) -> 2181.5 | F104: =E104/$E$4 -> 0.0023977112 | G104: =AVERAGE(M104,U104,W104,AC104,AE104) -> 2291.6 | H104: =G104/$G$4 -> 0.0026026252 | I104: =AVERAGE(O104,Q104,S104,Y104,AA104) -> 2071.4 | J104: =I104/$I$4 -> 0.0022055964 | K104: =AVERAGE(O104,Q104,S104) -> 2665 | L104: =K104/$K$4 -> 0.0022842635 | M104: 1203 | N104: =M104/$M$4 -> 0.0020426286 | O104: 2723 | P104: =O104/$O$4 -> 0.0023103192 | Q104: 2742 | R104: =Q104/$Q$4 -> 0.002276006 | S104: 2530 | T104: =S104/$S$4 -> 0.002265671 | U104: 2685 | V104: =U104/$U$4 -> 0.0028342158 | W104: 2796 | X104: =W104/$W$4 -> 0.0028169724 | Y104: 1188 | Z104: =Y104/$Y$4 -> 0.0020193538 | AA104: 1174 | AB104: =AA104/$AA$4 -> 0.001932698 | AC104: 2399 | AD104: =AC104/$AC$4 -> 0.0018511317 | AE104: 2375 | AF104: =AE104/$AE$4 -> 0.004111415 | AG104: 2565 | AH104: 1757 | AI104: 2286 | AJ104: 1717
A105: S GA | B105: Very Small | C105: Tallahassee, FL | D105: Decatur | E105: =AVERAGE(M105,O105,Q105,S105,U105,W105,Y105,AA105,AC105,AE105) -> 1998.3 | F105: =E105/$E$4 -> 0.002196354 | G105: =AVERAGE(M105,U105,W105,AC105,AE105) -> 1703.6 | H105: =G105/$G$4 -> 0.0019348194 | I105: =AVERAGE(O105,Q105,S105,Y105,AA105) -> 2293 | J105: =I105/$I$4 -> 0.0024415529 | K105: =AVERAGE(O105,Q105,S105) -> 2968.6667 | L105: =K105/$K$4 -> 0.0025445467 | M105: 1508 | N105: =M105/$M$4 -> 0.002560502 | O105: 3044 | P105: =O105/$O$4 -> 0.0025826705 | Q105: 3088 | R105: =Q105/$Q$4 -> 0.0025632044 | S105: 2774 | T105: =S105/$S$4 -> 0.0024841784 | U105: 1497 | V105: =U105/$U$4 -> 0.0015801941 | W105: 1538 | X105: =W105/$W$4 -> 0.0015495363 | Y105: 1451 | Z105: =Y105/$Y$4 -> 0.0024663993 | AA105: 1108 | AB105: =AA105/$AA$4 -> 0.0018240455 | AC105: 3161 | AD105: =AC105/$AC$4 -> 0.002439111 | AE105: 814 | AF105: =AE105/$AE$4 -> 0.0014091334 | AG105: 2939 | AH105: 2005 | AI105: 2551 | AJ105: 1850
A106: Coastal GA | B106: Very Small | C106: Savannah | D106: Liberty | E106: =AVERAGE(M106,O106,Q106,S106,U106,W106,Y106,AA106,AC106,AE106) -> 1989.7 | F106: =E106/$E$4 -> 0.0021869017 | G106: =AVERAGE(M106,U106,W106,AC106,AE106) -> 1626.2 | H106: =G106/$G$4 -> 0.0018469144 | I106: =AVERAGE(O106,Q106,S106,Y106,AA106) -> 2353.2 | J106: =I106/$I$4 -> 0.0025056529 | K106: =AVERAGE(O106,Q106,S106) -> 2884 | L106: =K106/$K$4 -> 0.002471976 | M106: 1450 | N106: =M106/$M$4 -> 0.0024620212 | O106: 2908 | P106: =O106/$O$4 -> 0.0024672818 | Q106: 2976 | R106: =Q106/$Q$4 -> 0.0024702384 | S106: 2768 | T106: =S106/$S$4 -> 0.0024788052 | U106: 1606 | V106: =U106/$U$4 -> 0.0016952516 | W106: 1706 | X106: =W106/$W$4 -> 0.0017187964 | Y106: 1297 | Z106: =Y106/$Y$4 -> 0.0022046313 | AA106: 1817 | AB106: =AA106/$AA$4 -> 0.002991237 | AC106: 2907 | AD106: =AC106/$AC$4 -> 0.0022431179 | AE106: 462 | AF106: =AE106/$AE$4 -> 0.00079977842 | AG106: 2808 | AH106: 2015 | AI106: 2379 | AJ106: 1861
A107: Middle GA | B107: Very Small | C107: Macon | D107: Bleckley | E107: =AVERAGE(M107,O107,Q107,S107,U107,W107,Y107,AA107,AC107,AE107) -> 1943.8 | F107: =E107/$E$4 -> 0.0021364525 | G107: =AVERAGE(M107,U107,W107,AC107,AE107) -> 1828.2 | H107: =G107/$G$4 -> 0.0020763306 | I107: =AVERAGE(O107,Q107,S107,Y107,AA107) -> 2059.4 | J107: =I107/$I$4 -> 0.002192819 | K107: =AVERAGE(O107,Q107,S107) -> 2506.6667 | L107: =K107/$K$4 -> 0.0021485506 | M107: 1064 | N107: =M107/$M$4 -> 0.0018066142 | O107: 2537 | P107: =O107/$O$4 -> 0.0021525082 | Q107: 2563 | R107: =Q107/$Q$4 -> 0.0021274265 | S107: 2420 | T107: =S107/$S$4 -> 0.0021671635 | U107: 1684 | V107: =U107/$U$4 -> 0.0017775864 | W107: 1756 | X107: =W107/$W$4 -> 0.0017691715 | Y107: 1164 | Z107: =Y107/$Y$4 -> 0.0019785588 | AA107: 1613 | AB107: =AA107/$AA$4 -> 0.0026554019 | AC107: 2144 | AD107: =AC107/$AC$4 -> 0.0016543669 | AE107: 2493 | AF107: =AE107/$AE$4 -> 0.0043156874 | AG107: 2426 | AH107: 1576 | AI107: 1990 | AJ107: 1406
A108: Coastal GA | B108: Very Small | C108: Savannah | D108: McIntosh | E108: =AVERAGE(M108,O108,Q108,S108,U108,W108,Y108,AA108,AC108,AE108) -> 1888.3 | F108: =E108/$E$4 -> 0.0020754518 | G108: =AVERAGE(M108,U108,W108,AC108,AE108) -> 1854.6 | H108: =G108/$G$4 -> 0.0021063138 | I108: =AVERAGE(O108,Q108,S108,Y108,AA108) -> 1922 | J108: =I108/$I$4 -> 0.0020465175 | K108: =AVERAGE(O108,Q108,S108) -> 2470 | L108: =K108/$K$4 -> 0.0021171223 | M108: 1308 | N108: =M108/$M$4 -> 0.0022209129 | O108: 2508 | P108: =O108/$O$4 -> 0.0021279033 | Q108: 2567 | R108: =Q108/$Q$4 -> 0.0021307467 | S108: 2335 | T108: =S108/$S$4 -> 0.0020910442 | U108: 2098 | V108: =U108/$U$4 -> 0.0022145939 | W108: 2144 | X108: =W108/$W$4 -> 0.0021600818 | Y108: 1040 | Z108: =Y108/$Y$4 -> 0.0017677845 | AA108: 1160 | AB108: =AA108/$AA$4 -> 0.0019096505 | AC108: 1999 | AD108: =AC108/$AC$4 -> 0.0015424811 | AE108: 1724 | AF108: =AE108/$AE$4 -> 0.0029844545 | AG108: 1842 | AH108: 1359 | AI108: 1606 | AJ108: 1196
A109: S GA | B109: Very Small | C109: Albany | D109: Mitchell | E109: =AVERAGE(M109,O109,Q109,S109,U109,W109,Y109,AA109,AC109,AE109) -> 1882 | F109: =E109/$E$4 -> 0.0020685274 | G109: =AVERAGE(M109,U109,W109,AC109,AE109) -> 1795.6 | H109: =G109/$G$4 -> 0.002039306 | I109: =AVERAGE(O109,Q109,S109,Y109,AA109) -> 1968.4 | J109: =I109/$I$4 -> 0.0020959235 | K109: =AVERAGE(O109,Q109,S109) -> 2562.6667 | L109: =K109/$K$4 -> 0.0021965501 | M109: 1218 | N109: =M109/$M$4 -> 0.0020680978 | O109: 2597 | P109: =O109/$O$4 -> 0.002203415 | Q109: 2615 | R109: =Q109/$Q$4 -> 0.0021705892 | S109: 2476 | T109: =S109/$S$4 -> 0.0022173128 | U109: 2137 | V109: =U109/$U$4 -> 0.0022557613 | W109: 2191 | X109: =W109/$W$4 -> 0.0022074343 | Y109: 1125 | Z109: =Y109/$Y$4 -> 0.0019122669 | AA109: 1029 | AB109: =AA109/$AA$4 -> 0.0016939917 | AC109: 2279 | AD109: =AC109/$AC$4 -> 0.0017585365 | AE109: 1153 | AF109: =AE109/$AE$4 -> 0.0019959838 | AG109: 2330 | AH109: 1602 | AI109: 1976 | AJ109: 1436
A110: S GA | B110: Very Small | C110: Savannah | D110: Jeff Davis | E110: =AVERAGE(M110,O110,Q110,S110,U110,W110,Y110,AA110,AC110,AE110) -> 1837.9 | F110: =E110/$E$4 -> 0.0020200566 | G110: =AVERAGE(M110,U110,W110,AC110,AE110) -> 2054.2 | H110: =G110/$G$4 -> 0.0023330043 | I110: =AVERAGE(O110,Q110,S110,Y110,AA110) -> 1621.6 | J110: =I110/$I$4 -> 0.001726656 | K110: =AVERAGE(O110,Q110,S110) -> 2071.3333 | L110: =K110/$K$4 -> 0.0017754113 | M110: 1095 | N110: =M110/$M$4 -> 0.0018592505 | O110: 2098 | P110: =O110/$O$4 -> 0.0017800403 | Q110: 2147 | R110: =Q110/$Q$4 -> 0.0017821243 | S110: 1969 | T110: =S110/$S$4 -> 0.0017632831 | U110: 2579 | V110: =U110/$U$4 -> 0.002722325 | W110: 2401 | X110: =W110/$W$4 -> 0.0024190095 | Y110: 862 | Z110: =Y110/$Y$4 -> 0.0014652214 | AA110: 1032 | AB110: =AA110/$AA$4 -> 0.0016989304 | AC110: 2287 | AD110: =AC110/$AC$4 -> 0.0017647095 | AE110: 1909 | AF110: =AE110/$AE$4 -> 0.0033047121 | AG110: 2036 | AH110: 1390 | AI110: 1621 | AJ110: 1080
... A164: Middle GA | B164: Micro | C164: Augusta | D164: Taliaferro | E164: =AVERAGE(M164,O164,Q164,S164,U164,W164,Y164,AA164,AC164,AE164) -> 125.8 | F164: =E164/$E$4 -> 0.0001382682 | G164: =AVERAGE(M164,U164,W164,AC164,AE164) -> 104.2 | H164: =G164/$G$4 -> 0.00011834244 | I164: =AVERAGE(O164,Q164,S164,Y164,AA164) -> 147.4 | J164: =I164/$I$4 -> 0.00015694936 | K164: =AVERAGE(O164,Q164,S164) -> 212 | L164: =K164/$K$4 -> 0.00018171252 | M164: 115 | N164: =M164/$M$4 -> 0.00019526375 | O164: 214 | P164: =O164/$O$4 -> 0.0001815675 | Q164: 220 | R164: =Q164/$Q$4 -> 0.00018261171 | S164: 202 | T164: =S164/$S$4 -> 0.00018089547 | U164: 90 | V164: =U164/$U$4 -> 9.5001647e-05 | W164: 98 | X164: =W164/$W$4 -> 9.8735083e-05 | Y164: 59 | Z164: =Y164/$Y$4 -> 0.00010028777 | AA164: 42 | AB164: =AA164/$AA$4 -> 6.9142518e-05 | AC164: 197 | AD164: =AC164/$AC$4 -> 0.0001520104 | AE164: 21 | AF164: =AE164/$AE$4 -> 3.6353564e-05 | AG164: 215 | AH164: 147 | AI164: 177 | AJ164: 123

Sheet Yr By Yr
C1: 2024 President | J1: 2022 US Senate | Q1: 2022 Governor | X1: 2022 Lt. Governor | AE1: 2020 President | AF1: 2020 US Senate | AG1: 2018 Governor Run Off | AL1: 2018 Governor Initial | AU1: 2016 Pres Preference | BD1: 2016 US Sen
A3: DMA | B3: County | C3: Trump | D3: Trump % | E3: Haley | F3: Haley % | G3: Other | H3: Other % | I3: Total | J3: Herschel Walker | K3: Walker % | L3: Gary Black | M3: Black % | N3: Other | O3: Other % | P3: Total | Q3: Brian Kemp | R3: Kemp % | S3: David Perdue | T3: Perdue % | U3: Other | V3: Other % | W3: Total | X3: Burt Jones | Y3: Jones % | Z3: Butch Miller | AA3: Miller % | AB3: Other | AC3: Other % | AD3: Total | AE3: Trump Total | AF3: Perdue Total | AG3: Brian Kemp | AH3: Kemp % | AI3: Casey Cagle | AJ3: Cagle % | AK3: Total | AL3: Casey Cagle | AM3: Cagle % | AN3: Brian Kemp | AO3: Kemp % | AP3: Hunter Hill | AQ3: Hill % | AR3: Other | AS3: Other % | AT3: Total | AU3: Trump | AV3: Trump % | AW3: Rubio | AX3: Rubio % | AY3: Cruz | AZ3: Cruz % | BA3: Other | BB3: Other % | BC3: Total | BD3: Johnny Isakson | BE3: Isakson % | BF3: Other | BG3: Other % | BH3: Total
A4: Savanna | B4: Appling | C4: 1791 | E4: 99 | G4: 12 | I4: 1902 | J4: 2879 | L4: 612 | N4: 212 | P4: 3703 | Q4: 2167 | S4: 792 | U4: 822 | W4: 3781 | X4: 1856 | Z4: 976 | AB4: 612 | AD4: 3444 | AE4: 3238 | AF4: 3348 | AG4: 1217 | AI4: 293 | AK4: 1510 | AL4: 440 | AN4: 627 | AP4: 627 | AR4: 222 | AT4: 1916 | AU4: 1291 | AW4: 462 | AY4: 914 | BA4: 446 | BC4: 3113 | BD4: 3061 | BF4: 1001 | BH4: 4062
A5: Albany | B5: Atkinson | C5: 464 | E5: 9 | G5: 4 | I5: 477 | J5: 732 | L5: 171 | N5: 73 | P5: 976 | Q5: 588 | S5: 323 | U5: 86 | W5: 997 | X5: 472 | Z5: 245 | AB5: 186 | AD5: 903 | AE5: 1361 | AF5: 1228 | AG5: 389 | AI5: 150 | AK5: 539 | AL5: 178 | AN5: 103 | AP5: 105 | AR5: 79 | AT5: 465 | AU5: 622 | AW5: 73 | AY5: 183 | BA5: 67 | BC5: 945 | BD5: 82 | BF5: 33 | BH5: 115
A6: Savanna | B6: Bacon | C6: 1043 | E6: 57 | G6: 13 | I6: 1113 | J6: 1735 | L6: 397 | N6: 180 | P6: 2312 | Q6: 1295 | S6: 650 | U6: 443 | W6: 2388 | X6: 960 | Z6: 608 | AB6: 504 | AD6: 2072 | AE6: 2310 | AF6: 2214 | AG6: 569 | AI6: 190 | AK6: 759 | AL6: 224 | AN6: 315 | AP6: 147 | AR6: 145 | AT6: 831 | AU6: 904 | AW6: 246 | AY6: 341 | BA6: 189 | BC6: 1680 | BD6: 1514 | BF6: 588 | BH6: 2102
A7: Albany | B7: Baker | C7: 241 | E7: 13 | G7: 1 | I7: 255 | J7: 271 | L7: 183 | N7: 20 | P7: 474 | Q7: 347 | S7: 107 | U7: 26 | W7: 480 | X7: 203 | Z7: 148 | AB7: 75 | AD7: 426 | AE7: 65 | AF7: 64 | AG7: 195 | AI7: 70 | AK7: 265 | AL7: 81 | AN7: 61 | AP7: 36 | AR7: 26 | AT7: 204 | AU7: 262 | AW7: 42 | AY7: 87 | BA7: 44 | BC7: 435 | BD7: 9 | BF7: 7 | BH7: 16
A8: Macon | B8: Baldwin | C8: 2135 | E8: 244 | G8: 40 | I8: 2419 | J8: 3779 | L8: 569 | N8: 408 | P8: 4756 | Q8: 3731 | S8: 907 | U8: 182 | W8: 4820 | X8: 3420 | Z8: 800 | AB8: 402 | AD8: 4622 | AE8: 3587 | AF8: 3779 | AG8: 1954 | AI8: 672 | AK8: 2626 | AL8: 872 | AN8: 707 | AP8: 427 | AR8: 343 | AT8: 2349 | AU8: 2070 | AW8: 962 | AY8: 883 | BA8: 612 | BC8: 4527 | BD8: 2656 | BF8: 454 | BH8: 3110
